Workbook
Name Noten: Einstellungen!$B$7:$B$12
Name NGrenze: Einstellungen!$C$7:$C$12
Name NText: Einstellungen!$D$7:$D$12
Name PktStd: Einstellungen!$C$16
Name SchwelleDB: Einstellungen!$C$17
Name GewAn: Einstellungen!$C$18
Name GewP: Einstellungen!$C$19
Name GewT: Einstellungen!$C$20
Name WdhStd: Einstellungen!$C$21
Name WarnNote: Einstellungen!$C$22
Name Berufe: Einstellungen!$B$25:$B$34
Name AzubiAuswahl: OFFSET(Daten!$D$2452,0,0,MAX(1,Daten!$B$2344),1)
Name AzubiAktiv: OFFSET(Daten!$D$2557,0,0,MAX(1,Daten!$B$2556),1)
Name JahrAuswahl: OFFSET(Daten!$C$2662,0,0,1+COUNT(Daten!$B$2663:$B$2762),1)
Name BerufAuswahl: OFFSET(Daten!$C$2769,0,0,1+COUNTIF(Berufe,"?*"),1)
Name HJAuswahl: Daten!$C$1703:$J$1703

Sheet Start
A1: Azubi-Leistungen
A2: Überblick über Übungen, Tests und den Leistungsstand – Startseite und Inhaltsverzeichnis
A3: Farben: gelb = hier eintragen · grau-blau = rechnet die Datei selbst · „n.b.“ = nicht bewertet | J3: Kurzanleitung öffnen »
A4: Azubi-Ansicht | C4: Gesprächsseite | E4: Halbjahr | G4: Übungen verwalten | J4: Stammdaten | L4: Einstellungen
A6: =COUNTIF('Stammdaten'!$G$6:$G$105,"aktiv") | C6: =SUM(Daten!$C$5:$V$5) | E6: =IF(SUM(Daten!$C$1385:$V$1484)=0,"",SUMPRODUCT(Daten!$C$1385:$V$1484,Daten!$C$20:$V$119)/SUM(Daten!$C$1385:$V$1484)) | G6: =SUM(Daten!$G$2347:$G$2446) | J6: =IF(SUM(Daten!$C$16:$V$16)+SUMPRODUCT((Daten!$C$5:$V$5=1)*(Daten!$C$7:$V$7=0))+SUMPRODUCT((Daten!$C$5:$V$5=1)*(Daten!$C$6:$V$6=""))+SUMPRODUCT((Daten!$C$5:$V$5=1)*(Daten!$C$13:$V$13=0))+SUMPRODUCT(('Stammdaten'!$B$6:$B$105<>"")*('Stammdaten'!$F$6:$F$105=""))+SUMPRODUCT(('Stammdaten'!$J$6:$J$105<>"")*(COUNTIF('Stammdaten'!$J$6:$J$105,'Stammdaten'!$J$6:$J$105&"")>1))>0,"ROT - bitte die Punkte rechts unten klären",IF(SUM(Daten!$C$17:$V$17)+SUM(Daten!$C$18:$V$18)+SUMPRODUCT(('Stammdaten'!$B$6:$B$105<>"")*('Stammdaten'!$G$6:$G$105=""))>0,"GELB - Kleinigkeiten fehlen noch","GRÜN - alle Angaben vollständig"))
A7: aktive Azubis | C7: belegte Übungen | E7: Ø aller Bewertungen | G7: Azubis in der Warnübersicht
A9: Übungen – Kennzahlen und Sprung zum Blatt | J9: Datenprüfung
A10: Nr. | B10: Übung (anklicken) | C10: Art | D10: Datum | E10: Status | F10: bewertet | G10: Ø Prozent | H10: Ø IHK-Note | J10: Azubis ohne Ausbildungsstart | M10: =SUMPRODUCT(('Stammdaten'!$B$6:$B$105<>"")*('Stammdaten'!$F$6:$F$105=""))
A11: 1 | B11: =IF('Übungen'!$C6="","(frei – Übung 01)",'Übungen'!$C6) | C11: =IF('Übungen'!$C6="","",Daten!C$6) | D11: =IF('Übungen'!$C6="","",IF(Daten!C$7=0,"",Daten!C$7)) | E11: =IF('Übungen'!$C6="","",Daten!C$8) | F11: ='Übungen'!$L6 | G11: ='Übungen'!$M6 | H11: ='Übungen'!$N6 | J11: Azubis ohne Status | M11: =SUMPRODUCT(('Stammdaten'!$B$6:$B$105<>"")*('Stammdaten'!$G$6:$G$105=""))
A12: 2 | B12: =IF('Übungen'!$C7="","(frei – Übung 02)",'Übungen'!$C7) | C12: =IF('Übungen'!$C7="","",Daten!D$6) | D12: =IF('Übungen'!$C7="","",IF(Daten!D$7=0,"",Daten!D$7)) | E12: =IF('Übungen'!$C7="","",Daten!D$8) | F12: ='Übungen'!$L7 | G12: ='Übungen'!$M7 | H12: ='Übungen'!$N7 | J12: Übungen ohne Datum | M12: =SUMPRODUCT((Daten!$C$5:$V$5=1)*(Daten!$C$7:$V$7=0))
A13: 3 | B13: =IF('Übungen'!$C8="","(frei – Übung 03)",'Übungen'!$C8) | C13: =IF('Übungen'!$C8="","",Daten!E$6) | D13: =IF('Übungen'!$C8="","",IF(Daten!E$7=0,"",Daten!E$7)) | E13: =IF('Übungen'!$C8="","",Daten!E$8) | F13: ='Übungen'!$L8 | G13: ='Übungen'!$M8 | H13: ='Übungen'!$N8 | J13: Übungen ohne Art (Praxis/Theorie) | M13: =SUMPRODUCT((Daten!$C$5:$V$5=1)*(Daten!$C$6:$V$6=""))
A14: 4 | B14: =IF('Übungen'!$C9="","(frei – Übung 04)",'Übungen'!$C9) | C14: =IF('Übungen'!$C9="","",Daten!F$6) | D14: =IF('Übungen'!$C9="","",IF(Daten!F$7=0,"",Daten!F$7)) | E14: =IF('Übungen'!$C9="","",Daten!F$8) | F14: ='Übungen'!$L9 | G14: ='Übungen'!$M9 | H14: ='Übungen'!$N9 | J14: Übungen ohne Bewertungsparameter | M14: =SUMPRODUCT((Daten!$C$5:$V$5=1)*(Daten!$C$13:$V$13=0))
A15: 5 | B15: =IF('Übungen'!$C10="","(frei – Übung 05)",'Übungen'!$C10) | C15: =IF('Übungen'!$C10="","",Daten!G$6) | D15: =IF('Übungen'!$C10="","",IF(Daten!G$7=0,"",Daten!G$7)) | E15: =IF('Übungen'!$C10="","",Daten!G$8) | F15: ='Übungen'!$L10 | G15: ='Übungen'!$M10 | H15: ='Übungen'!$N10 | J15: angefangene, unvollständige Zeilen | M15: =SUM(Daten!$C$16:$V$16)
A16: 6 | B16: =IF('Übungen'!$C11="","(frei – Übung 06)",'Übungen'!$C11) | C16: =IF('Übungen'!$C11="","",Daten!H$6) | D16: =IF('Übungen'!$C11="","",IF(Daten!H$7=0,"",Daten!H$7)) | E16: =IF('Übungen'!$C11="","",Daten!H$8) | F16: ='Übungen'!$L11 | G16: ='Übungen'!$M11 | H16: ='Übungen'!$N11 | J16: ganze Zeile „n.b.“ ohne Grund | M16: =SUM(Daten!$C$17:$V$17)
A17: 7 | B17: =IF('Übungen'!$C12="","(frei – Übung 07)",'Übungen'!$C12) | C17: =IF('Übungen'!$C12="","",Daten!I$6) | D17: =IF('Übungen'!$C12="","",IF(Daten!I$7=0,"",Daten!I$7)) | E17: =IF('Übungen'!$C12="","",Daten!I$8) | F17: ='Übungen'!$L12 | G17: ='Übungen'!$M12 | H17: ='Übungen'!$N12 | J17: Übungen ohne Kürzel „Bewertet von“ | M17: =SUM(Daten!$C$18:$V$18)
A18: 8 | B18: =IF('Übungen'!$C13="","(frei – Übung 08)",'Übungen'!$C13) | C18: =IF('Übungen'!$C13="","",Daten!J$6) | D18: =IF('Übungen'!$C13="","",IF(Daten!J$7=0,"",Daten!J$7)) | E18: =IF('Übungen'!$C13="","",Daten!J$8) | F18: ='Übungen'!$L13 | G18: ='Übungen'!$M13 | H18: ='Übungen'!$N13 | J18: Azubis mit gleichem Namen | M18: =SUMPRODUCT(('Stammdaten'!$J$6:$J$105<>"")*(COUNTIF('Stammdaten'!$J$6:$J$105,'Stammdaten'!$J$6:$J$105&"")>1))
A19: 9 | B19: =IF('Übungen'!$C14="","(frei – Übung 09)",'Übungen'!$C14) | C19: =IF('Übungen'!$C14="","",Daten!K$6) | D19: =IF('Übungen'!$C14="","",IF(Daten!K$7=0,"",Daten!K$7)) | E19: =IF('Übungen'!$C14="","",Daten!K$8) | F19: ='Übungen'!$L14 | G19: ='Übungen'!$M14 | H19: ='Übungen'!$N14 | J19: =" Warnübersicht – zuletzt Note "&WarnNote&" oder schlechter"
A20: 10 | B20: =IF('Übungen'!$C15="","(frei – Übung 10)",'Übungen'!$C15) | C20: =IF('Übungen'!$C15="","",Daten!L$6) | D20: =IF('Übungen'!$C15="","",IF(Daten!L$7=0,"",Daten!L$7)) | E20: =IF('Übungen'!$C15="","",Daten!L$8) | F20: ='Übungen'!$L15 | G20: ='Übungen'!$M15 | H20: ='Übungen'!$N15 | J20: Azubi | K20: LJ / HJ | L20: Prozent | M20: IHK-Note
A21: 11 | B21: =IF('Übungen'!$C16="","(frei – Übung 11)",'Übungen'!$C16) | C21: =IF('Übungen'!$C16="","",Daten!M$6) | D21: =IF('Übungen'!$C16="","",IF(Daten!M$7=0,"",Daten!M$7)) | E21: =IF('Übungen'!$C16="","",Daten!M$8) | F21: ='Übungen'!$L16 | G21: ='Übungen'!$M16 | H21: ='Übungen'!$N16 | J21: =IF(IFERROR(SMALL(Daten!$H$2347:$H$2446,1),"")="","",INDEX('Stammdaten'!$J$6:$J$105,IFERROR(SMALL(Daten!$H$2347:$H$2446,1),""))) | K21: =IF(IFERROR(SMALL(Daten!$H$2347:$H$2446,1),"")="","",INDEX('Stammdaten'!$H$6:$H$105,IFERROR(SMALL(Daten!$H$2347:$H$2446,1),""))&" / "&INDEX(Daten!$C$2347:$C$2446,IFERROR(SMALL(Daten!$H$2347:$H$2446,1),""))) | L21: =IF(IFERROR(SMALL(Daten!$H$2347:$H$2446,1),"")="","",INDEX(Daten!$D$2347:$D$2446,IFERROR(SMALL(Daten!$H$2347:$H$2446,1),""))) | M21: =IF($L21="","",INDEX(Noten,MAX(1,MIN(COUNT(NGrenze),COUNT(NGrenze)+1-COUNTIF(NGrenze,"<="&$L21))))&" – "&INDEX(NText,MAX(1,MIN(COUNT(NGrenze),COUNT(NGrenze)+1-COUNTIF(NGrenze,"<="&$L21)))))
A22: 12 | B22: =IF('Übungen'!$C17="","(frei – Übung 12)",'Übungen'!$C17) | C22: =IF('Übungen'!$C17="","",Daten!N$6) | D22: =IF('Übungen'!$C17="","",IF(Daten!N$7=0,"",Daten!N$7)) | E22: =IF('Übungen'!$C17="","",Daten!N$8) | F22: ='Übungen'!$L17 | G22: ='Übungen'!$M17 | H22: ='Übungen'!$N17 | J22: =IF(IFERROR(SMALL(Daten!$H$2347:$H$2446,2),"")="","",INDEX('Stammdaten'!$J$6:$J$105,IFERROR(SMALL(Daten!$H$2347:$H$2446,2),""))) | K22: =IF(IFERROR(SMALL(Daten!$H$2347:$H$2446,2),"")="","",INDEX('Stammdaten'!$H$6:$H$105,IFERROR(SMALL(Daten!$H$2347:$H$2446,2),""))&" / "&INDEX(Daten!$C$2347:$C$2446,IFERROR(SMALL(Daten!$H$2347:$H$2446,2),""))) | L22: =IF(IFERROR(SMALL(Daten!$H$2347:$H$2446,2),"")="","",INDEX(Daten!$D$2347:$D$2446,IFERROR(SMALL(Daten!$H$2347:$H$2446,2),""))) | M22: =IF($L22="","",INDEX(Noten,MAX(1,MIN(COUNT(NGrenze),COUNT(NGrenze)+1-COUNTIF(NGrenze,"<="&$L22))))&" – "&INDEX(NText,MAX(1,MIN(COUNT(NGrenze),COUNT(NGrenze)+1-COUNTIF(NGrenze,"<="&$L22)))))
A23: 13 | B23: =IF('Übungen'!$C18="","(frei – Übung 13)",'Übungen'!$C18) | C23: =IF('Übungen'!$C18="","",Daten!O$6) | D23: =IF('Übungen'!$C18="","",IF(Daten!O$7=0,"",Daten!O$7)) | E23: =IF('Übungen'!$C18="","",Daten!O$8) | F23: ='Übungen'!$L18 | G23: ='Übungen'!$M18 | H23: ='Übungen'!$N18 | J23: =IF(IFERROR(SMALL(Daten!$H$2347:$H$2446,3),"")="","",INDEX('Stammdaten'!$J$6:$J$105,IFERROR(SMALL(Daten!$H$2347:$H$2446,3),""))) | K23: =IF(IFERROR(SMALL(Daten!$H$2347:$H$2446,3),"")="","",INDEX('Stammdaten'!$H$6:$H$105,IFERROR(SMALL(Daten!$H$2347:$H$2446,3),""))&" / "&INDEX(Daten!$C$2347:$C$2446,IFERROR(SMALL(Daten!$H$2347:$H$2446,3),""))) | L23: =IF(IFERROR(SMALL(Daten!$H$2347:$H$2446,3),"")="","",INDEX(Daten!$D$2347:$D$2446,IFERROR(SMALL(Daten!$H$2347:$H$2446,3),""))) | M23: =IF($L23="","",INDEX(Noten,MAX(1,MIN(COUNT(NGrenze),COUNT(NGrenze)+1-COUNTIF(NGrenze,"<="&$L23))))&" – "&INDEX(NText,MAX(1,MIN(COUNT(NGrenze),COUNT(NGrenze)+1-COUNTIF(NGrenze,"<="&$L23)))))
A24: 14 | B24: =IF('Übungen'!$C19="","(frei – Übung 14)",'Übungen'!$C19) | C24: =IF('Übungen'!$C19="","",Daten!P$6) | D24: =IF('Übungen'!$C19="","",IF(Daten!P$7=0,"",Daten!P$7)) | E24: =IF('Übungen'!$C19="","",Daten!P$8) | F24: ='Übungen'!$L19 | G24: ='Übungen'!$M19 | H24: ='Übungen'!$N19 | J24: =IF(IFERROR(SMALL(Daten!$H$2347:$H$2446,4),"")="","",INDEX('Stammdaten'!$J$6:$J$105,IFERROR(SMALL(Daten!$H$2347:$H$2446,4),""))) | K24: =IF(IFERROR(SMALL(Daten!$H$2347:$H$2446,4),"")="","",INDEX('Stammdaten'!$H$6:$H$105,IFERROR(SMALL(Daten!$H$2347:$H$2446,4),""))&" / "&INDEX(Daten!$C$2347:$C$2446,IFERROR(SMALL(Daten!$H$2347:$H$2446,4),""))) | L24: =IF(IFERROR(SMALL(Daten!$H$2347:$H$2446,4),"")="","",INDEX(Daten!$D$2347:$D$2446,IFERROR(SMALL(Daten!$H$2347:$H$2446,4),""))) | M24: =IF($L24="","",INDEX(Noten,MAX(1,MIN(COUNT(NGrenze),COUNT(NGrenze)+1-COUNTIF(NGrenze,"<="&$L24))))&" – "&INDEX(NText,MAX(1,MIN(COUNT(NGrenze),COUNT(NGrenze)+1-COUNTIF(NGrenze,"<="&$L24)))))
A25: 15 | B25: =IF('Übungen'!$C20="","(frei – Übung 15)",'Übungen'!$C20) | C25: =IF('Übungen'!$C20="","",Daten!Q$6) | D25: =IF('Übungen'!$C20="","",IF(Daten!Q$7=0,"",Daten!Q$7)) | E25: =IF('Übungen'!$C20="","",Daten!Q$8) | F25: ='Übungen'!$L20 | G25: ='Übungen'!$M20 | H25: ='Übungen'!$N20 | J25: =IF(IFERROR(SMALL(Daten!$H$2347:$H$2446,5),"")="","",INDEX('Stammdaten'!$J$6:$J$105,IFERROR(SMALL(Daten!$H$2347:$H$2446,5),""))) | K25: =IF(IFERROR(SMALL(Daten!$H$2347:$H$2446,5),"")="","",INDEX('Stammdaten'!$H$6:$H$105,IFERROR(SMALL(Daten!$H$2347:$H$2446,5),""))&" / "&INDEX(Daten!$C$2347:$C$2446,IFERROR(SMALL(Daten!$H$2347:$H$2446,5),""))) | L25: =IF(IFERROR(SMALL(Daten!$H$2347:$H$2446,5),"")="","",INDEX(Daten!$D$2347:$D$2446,IFERROR(SMALL(Daten!$H$2347:$H$2446,5),""))) | M25: =IF($L25="","",INDEX(Noten,MAX(1,MIN(COUNT(NGrenze),COUNT(NGrenze)+1-COUNTIF(NGrenze,"<="&$L25))))&" – "&INDEX(NText,MAX(1,MIN(COUNT(NGrenze),COUNT(NGrenze)+1-COUNTIF(NGrenze,"<="&$L25)))))
A26: 16 | B26: =IF('Übungen'!$C21="","(frei – Übung 16)",'Übungen'!$C21) | C26: =IF('Übungen'!$C21="","",Daten!R$6) | D26: =IF('Übungen'!$C21="","",IF(Daten!R$7=0,"",Daten!R$7)) | E26: =IF('Übungen'!$C21="","",Daten!R$8) | F26: ='Übungen'!$L21 | G26: ='Übungen'!$M21 | H26: ='Übungen'!$N21 | J26: =IF(IFERROR(SMALL(Daten!$H$2347:$H$2446,6),"")="","",INDEX('Stammdaten'!$J$6:$J$105,IFERROR(SMALL(Daten!$H$2347:$H$2446,6),""))) | K26: =IF(IFERROR(SMALL(Daten!$H$2347:$H$2446,6),"")="","",INDEX('Stammdaten'!$H$6:$H$105,IFERROR(SMALL(Daten!$H$2347:$H$2446,6),""))&" / "&INDEX(Daten!$C$2347:$C$2446,IFERROR(SMALL(Daten!$H$2347:$H$2446,6),""))) | L26: =IF(IFERROR(SMALL(Daten!$H$2347:$H$2446,6),"")="","",INDEX(Daten!$D$2347:$D$2446,IFERROR(SMALL(Daten!$H$2347:$H$2446,6),""))) | M26: =IF($L26="","",INDEX(Noten,MAX(1,MIN(COUNT(NGrenze),COUNT(NGrenze)+1-COUNTIF(NGrenze,"<="&$L26))))&" – "&INDEX(NText,MAX(1,MIN(COUNT(NGrenze),COUNT(NGrenze)+1-COUNTIF(NGrenze,"<="&$L26)))))
A27: 17 | B27: =IF('Übungen'!$C22="","(frei – Übung 17)",'Übungen'!$C22) | C27: =IF('Übungen'!$C22="","",Daten!S$6) | D27: =IF('Übungen'!$C22="","",IF(Daten!S$7=0,"",Daten!S$7)) | E27: =IF('Übungen'!$C22="","",Daten!S$8) | F27: ='Übungen'!$L22 | G27: ='Übungen'!$M22 | H27: ='Übungen'!$N22 | J27: =IF(IFERROR(SMALL(Daten!$H$2347:$H$2446,7),"")="","",INDEX('Stammdaten'!$J$6:$J$105,IFERROR(SMALL(Daten!$H$2347:$H$2446,7),""))) | K27: =IF(IFERROR(SMALL(Daten!$H$2347:$H$2446,7),"")="","",INDEX('Stammdaten'!$H$6:$H$105,IFERROR(SMALL(Daten!$H$2347:$H$2446,7),""))&" / "&INDEX(Daten!$C$2347:$C$2446,IFERROR(SMALL(Daten!$H$2347:$H$2446,7),""))) | L27: =IF(IFERROR(SMALL(Daten!$H$2347:$H$2446,7),"")="","",INDEX(Daten!$D$2347:$D$2446,IFERROR(SMALL(Daten!$H$2347:$H$2446,7),""))) | M27: =IF($L27="","",INDEX(Noten,MAX(1,MIN(COUNT(NGrenze),COUNT(NGrenze)+1-COUNTIF(NGrenze,"<="&$L27))))&" – "&INDEX(NText,MAX(1,MIN(COUNT(NGrenze),COUNT(NGrenze)+1-COUNTIF(NGrenze,"<="&$L27)))))
A28: 18 | B28: =IF('Übungen'!$C23="","(frei – Übung 18)",'Übungen'!$C23) | C28: =IF('Übungen'!$C23="","",Daten!T$6) | D28: =IF('Übungen'!$C23="","",IF(Daten!T$7=0,"",Daten!T$7)) | E28: =IF('Übungen'!$C23="","",Daten!T$8) | F28: ='Übungen'!$L23 | G28: ='Übungen'!$M23 | H28: ='Übungen'!$N23 | J28: =IF(IFERROR(SMALL(Daten!$H$2347:$H$2446,8),"")="","",INDEX('Stammdaten'!$J$6:$J$105,IFERROR(SMALL(Daten!$H$2347:$H$2446,8),""))) | K28: =IF(IFERROR(SMALL(Daten!$H$2347:$H$2446,8),"")="","",INDEX('Stammdaten'!$H$6:$H$105,IFERROR(SMALL(Daten!$H$2347:$H$2446,8),""))&" / "&INDEX(Daten!$C$2347:$C$2446,IFERROR(SMALL(Daten!$H$2347:$H$2446,8),""))) | L28: =IF(IFERROR(SMALL(Daten!$H$2347:$H$2446,8),"")="","",INDEX(Daten!$D$2347:$D$2446,IFERROR(SMALL(Daten!$H$2347:$H$2446,8),""))) | M28: =IF($L28="","",INDEX(Noten,MAX(1,MIN(COUNT(NGrenze),COUNT(NGrenze)+1-COUNTIF(NGrenze,"<="&$L28))))&" – "&INDEX(NText,MAX(1,MIN(COUNT(NGrenze),COUNT(NGrenze)+1-COUNTIF(NGrenze,"<="&$L28)))))
A29: 19 | B29: =IF('Übungen'!$C24="","(frei – Übung 19)",'Übungen'!$C24) | C29: =IF('Übungen'!$C24="","",Daten!U$6) | D29: =IF('Übungen'!$C24="","",IF(Daten!U$7=0,"",Daten!U$7)) | E29: =IF('Übungen'!$C24="","",Daten!U$8) | F29: ='Übungen'!$L24 | G29: ='Übungen'!$M24 | H29: ='Übungen'!$N24 | J29: =IF(IFERROR(SMALL(Daten!$H$2347:$H$2446,9),"")="","",INDEX('Stammdaten'!$J$6:$J$105,IFERROR(SMALL(Daten!$H$2347:$H$2446,9),""))) | K29: =IF(IFERROR(SMALL(Daten!$H$2347:$H$2446,9),"")="","",INDEX('Stammdaten'!$H$6:$H$105,IFERROR(SMALL(Daten!$H$2347:$H$2446,9),""))&" / "&INDEX(Daten!$C$2347:$C$2446,IFERROR(SMALL(Daten!$H$2347:$H$2446,9),""))) | L29: =IF(IFERROR(SMALL(Daten!$H$2347:$H$2446,9),"")="","",INDEX(Daten!$D$2347:$D$2446,IFERROR(SMALL(Daten!$H$2347:$H$2446,9),""))) | M29: =IF($L29="","",INDEX(Noten,MAX(1,MIN(COUNT(NGrenze),COUNT(NGrenze)+1-COUNTIF(NGrenze,"<="&$L29))))&" – "&INDEX(NText,MAX(1,MIN(COUNT(NGrenze),COUNT(NGrenze)+1-COUNTIF(NGrenze,"<="&$L29)))))
A30: 20 | B30: =IF('Übungen'!$C25="","(frei – Übung 20)",'Übungen'!$C25) | C30: =IF('Übungen'!$C25="","",Daten!V$6) | D30: =IF('Übungen'!$C25="","",IF(Daten!V$7=0,"",Daten!V$7)) | E30: =IF('Übungen'!$C25="","",Daten!V$8) | F30: ='Übungen'!$L25 | G30: ='Übungen'!$M25 | H30: ='Übungen'!$N25 | J30: =IF(IFERROR(SMALL(Daten!$H$2347:$H$2446,10),"")="","",INDEX('Stammdaten'!$J$6:$J$105,IFERROR(SMALL(Daten!$H$2347:$H$2446,10),""))) | K30: =IF(IFERROR(SMALL(Daten!$H$2347:$H$2446,10),"")="","",INDEX('Stammdaten'!$H$6:$H$105,IFERROR(SMALL(Daten!$H$2347:$H$2446,10),""))&" / "&INDEX(Daten!$C$2347:$C$2446,IFERROR(SMALL(Daten!$H$2347:$H$2446,10),""))) | L30: =IF(IFERROR(SMALL(Daten!$H$2347:$H$2446,10),"")="","",INDEX(Daten!$D$2347:$D$2446,IFERROR(SMALL(Daten!$H$2347:$H$2446,10),""))) | M30: =IF($L30="","",INDEX(Noten,MAX(1,MIN(COUNT(NGrenze),COUNT(NGrenze)+1-COUNTIF(NGrenze,"<="&$L30))))&" – "&INDEX(NText,MAX(1,MIN(COUNT(NGrenze),COUNT(NGrenze)+1-COUNTIF(NGrenze,"<="&$L30)))))
J31: =IF(SUM(Daten!$G$2347:$G$2446)>10,"… und "&(SUM(Daten!$G$2347:$G$2446)-10)&" weitere – vollständige Liste im Blatt „Halbjahr“","")
A32: Farblegende | C32: =INDEX(Noten,1)&" – "&INDEX(NText,1)&" (ab "&TEXT(INDEX(NGrenze,1)*100,"0")&" %)" | E32: =INDEX(Noten,2)&" – "&INDEX(NText,2)&" (ab "&TEXT(INDEX(NGrenze,2)*100,"0")&" %)" | G32: =INDEX(Noten,3)&" – "&INDEX(NText,3)&" (ab "&TEXT(INDEX(NGrenze,3)*100,"0")&" %)" | I32: =INDEX(Noten,4)&" – "&INDEX(NText,4)&" (ab "&TEXT(INDEX(NGrenze,4)*100,"0")&" %)" | K32: =INDEX(Noten,5)&" – "&INDEX(NText,5)&" (ab "&TEXT(INDEX(NGrenze,5)*100,"0")&" %)" | M32: =INDEX(Noten,6)&" – "&INDEX(NText,6)&" (ab "&TEXT(INDEX(NGrenze,6)*100,"0")&" %)"
A34: Farbe und Zahl sagen immer dasselbe – die Datei bleibt in Schwarz-Weiß und für Farbenblinde lesbar. Die Prozentgrenzen stehen im Blatt „Einstellungen“; wer sie dort ändert, ändert die Einfärbung überall mit. Die Datei liegt auf SharePoint: frühere Stände holt man über Datei > Informationen > Versionsverlauf zurück. Die Warnübersicht rechts bezieht sich auf das zuletzt bewertete Halbjahr des jeweiligen Azubis.

Sheet Azubi-Ansicht
A1: Azubi-Ansicht | J1: « Zurück zur Startseite
A2: Alles zu einem Azubi: laufende Projekte, bewertete Übungen, Halbjahre und Verlauf
A3: Farben: gelb = hier eintragen · grau-blau = rechnet die Datei selbst · „n.b.“ = nicht bewertet
A4: Filter Ausbildungsberuf | C4: (alle) | F4: Filter Jahrgang | H4: (alle) | J4: ="Azubis im Filter: "&Daten!$B$2344
A5: Azubi auswählen | C5: Berger, Lukas | F5: =IF(Daten!$B$2340=0,"Bitte oben einen Azubi auswählen – die Liste zeigt nur aktive Azubis, die zum Filter passen.","Ausgewählt: "&Daten!$B$2339)
A7: Name, Vorname | C7: Ausbildungsberuf | F7: Jahrgang | H7: Ausbildungsstart | J7: Lehrjahr | L7: aktuelles Halbjahr
A8: =IF(Daten!$B$2340=0,"–",INDEX('Stammdaten'!$J$6:$J$105,Daten!$B$2340)) | C8: =IF(Daten!$B$2340=0,"–",INDEX('Stammdaten'!$D$6:$D$105,Daten!$B$2340)) | F8: =IF(Daten!$B$2340=0,"–",INDEX('Stammdaten'!$E$6:$E$105,Daten!$B$2340)) | H8: =IF(Daten!$B$2340=0,"–",INDEX('Stammdaten'!$F$6:$F$105,Daten!$B$2340)) | J8: =IF(Daten!$B$2340=0,"–",INDEX('Stammdaten'!$H$6:$H$105,Daten!$B$2340)) | L8: =IF(Daten!$B$2340=0,"–",INDEX('Stammdaten'!$I$6:$I$105,Daten!$B$2340))
A10: Aktuell laufende Projekte
A11: Nr. | B11: Übung | C11: Art | D11: Datum | E11: Stand Punkte | F11: von max. | G11: Prozent | H11: Halbjahr | I11: Hinweis
A12: =IFERROR(SMALL(Daten!$C$2336:$V$2336,1),"") | B12: =IF($A12="","",INDEX(Daten!$C$4:$V$4,$A12)) | C12: =IF($A12="","",INDEX(Daten!$C$6:$V$6,$A12)) | D12: =IF($A12="","",IF(INDEX(Daten!$C$7:$V$7,$A12)=0,"",INDEX(Daten!$C$7:$V$7,$A12))) | E12: =IF($A12="","",INDEX(Daten!$C$335:$V$434,Daten!$B$2340,$A12)) | F12: =IF($A12="","",INDEX(Daten!$C$440:$V$539,Daten!$B$2340,$A12)) | G12: =IF($A12="","",IF(INDEX(Daten!$C$125:$V$224,Daten!$B$2340,$A12)=0,"",INDEX(Daten!$C$20:$V$119,Daten!$B$2340,$A12))) | H12: =IF($A12="","",IF(INDEX(Daten!$C$230:$V$329,Daten!$B$2340,$A12)=0,"–",INDEX(Daten!$C$230:$V$329,Daten!$B$2340,$A12))) | I12: =IF($A12="","",IF(INDEX(Daten!$C$125:$V$224,Daten!$B$2340,$A12)=1,"Zwischenstand – Übung läuft noch",IF(INDEX(Daten!$C$755:$V$854,Daten!$B$2340,$A12)=0,"noch nichts eingetragen","nicht bewertet"&IF(INDEX(Daten!$C$545:$V$644,Daten!$B$2340,$A12)="",""," ("&INDEX(Daten!$C$545:$V$644,Daten!$B$2340,$A12)&")"))))
A13: =IFERROR(SMALL(Daten!$C$2336:$V$2336,2),"") | B13: =IF($A13="","",INDEX(Daten!$C$4:$V$4,$A13)) | C13: =IF($A13="","",INDEX(Daten!$C$6:$V$6,$A13)) | D13: =IF($A13="","",IF(INDEX(Daten!$C$7:$V$7,$A13)=0,"",INDEX(Daten!$C$7:$V$7,$A13))) | E13: =IF($A13="","",INDEX(Daten!$C$335:$V$434,Daten!$B$2340,$A13)) | F13: =IF($A13="","",INDEX(Daten!$C$440:$V$539,Daten!$B$2340,$A13)) | G13: =IF($A13="","",IF(INDEX(Daten!$C$125:$V$224,Daten!$B$2340,$A13)=0,"",INDEX(Daten!$C$20:$V$119,Daten!$B$2340,$A13))) | H13: =IF($A13="","",IF(INDEX(Daten!$C$230:$V$329,Daten!$B$2340,$A13)=0,"–",INDEX(Daten!$C$230:$V$329,Daten!$B$2340,$A13))) | I13: =IF($A13="","",IF(INDEX(Daten!$C$125:$V$224,Daten!$B$2340,$A13)=1,"Zwischenstand – Übung läuft noch",IF(INDEX(Daten!$C$755:$V$854,Daten!$B$2340,$A13)=0,"noch nichts eingetragen","nicht bewertet"&IF(INDEX(Daten!$C$545:$V$644,Daten!$B$2340,$A13)="",""," ("&INDEX(Daten!$C$545:$V$644,Daten!$B$2340,$A13)&")"))))
A14: =IFERROR(SMALL(Daten!$C$2336:$V$2336,3),"") | B14: =IF($A14="","",INDEX(Daten!$C$4:$V$4,$A14)) | C14: =IF($A14="","",INDEX(Daten!$C$6:$V$6,$A14)) | D14: =IF($A14="","",IF(INDEX(Daten!$C$7:$V$7,$A14)=0,"",INDEX(Daten!$C$7:$V$7,$A14))) | E14: =IF($A14="","",INDEX(Daten!$C$335:$V$434,Daten!$B$2340,$A14)) | F14: =IF($A14="","",INDEX(Daten!$C$440:$V$539,Daten!$B$2340,$A14)) | G14: =IF($A14="","",IF(INDEX(Daten!$C$125:$V$224,Daten!$B$2340,$A14)=0,"",INDEX(Daten!$C$20:$V$119,Daten!$B$2340,$A14))) | H14: =IF($A14="","",IF(INDEX(Daten!$C$230:$V$329,Daten!$B$2340,$A14)=0,"–",INDEX(Daten!$C$230:$V$329,Daten!$B$2340,$A14))) | I14: =IF($A14="","",IF(INDEX(Daten!$C$125:$V$224,Daten!$B$2340,$A14)=1,"Zwischenstand – Übung läuft noch",IF(INDEX(Daten!$C$755:$V$854,Daten!$B$2340,$A14)=0,"noch nichts eingetragen","nicht bewertet"&IF(INDEX(Daten!$C$545:$V$644,Daten!$B$2340,$A14)="",""," ("&INDEX(Daten!$C$545:$V$644,Daten!$B$2340,$A14)&")"))))
A15: =IFERROR(SMALL(Daten!$C$2336:$V$2336,4),"") | B15: =IF($A15="","",INDEX(Daten!$C$4:$V$4,$A15)) | C15: =IF($A15="","",INDEX(Daten!$C$6:$V$6,$A15)) | D15: =IF($A15="","",IF(INDEX(Daten!$C$7:$V$7,$A15)=0,"",INDEX(Daten!$C$7:$V$7,$A15))) | E15: =IF($A15="","",INDEX(Daten!$C$335:$V$434,Daten!$B$2340,$A15)) | F15: =IF($A15="","",INDEX(Daten!$C$440:$V$539,Daten!$B$2340,$A15)) | G15: =IF($A15="","",IF(INDEX(Daten!$C$125:$V$224,Daten!$B$2340,$A15)=0,"",INDEX(Daten!$C$20:$V$119,Daten!$B$2340,$A15))) | H15: =IF($A15="","",IF(INDEX(Daten!$C$230:$V$329,Daten!$B$2340,$A15)=0,"–",INDEX(Daten!$C$230:$V$329,Daten!$B$2340,$A15))) | I15: =IF($A15="","",IF(INDEX(Daten!$C$125:$V$224,Daten!$B$2340,$A15)=1,"Zwischenstand – Übung läuft noch",IF(INDEX(Daten!$C$755:$V$854,Daten!$B$2340,$A15)=0,"noch nichts eingetragen","nicht bewertet"&IF(INDEX(Daten!$C$545:$V$644,Daten!$B$2340,$A15)="",""," ("&INDEX(Daten!$C$545:$V$644,Daten!$B$2340,$A15)&")"))))
A16: =IFERROR(SMALL(Daten!$C$2336:$V$2336,5),"") | B16: =IF($A16="","",INDEX(Daten!$C$4:$V$4,$A16)) | C16: =IF($A16="","",INDEX(Daten!$C$6:$V$6,$A16)) | D16: =IF($A16="","",IF(INDEX(Daten!$C$7:$V$7,$A16)=0,"",INDEX(Daten!$C$7:$V$7,$A16))) | E16: =IF($A16="","",INDEX(Daten!$C$335:$V$434,Daten!$B$2340,$A16)) | F16: =IF($A16="","",INDEX(Daten!$C$440:$V$539,Daten!$B$2340,$A16)) | G16: =IF($A16="","",IF(INDEX(Daten!$C$125:$V$224,Daten!$B$2340,$A16)=0,"",INDEX(Daten!$C$20:$V$119,Daten!$B$2340,$A16))) | H16: =IF($A16="","",IF(INDEX(Daten!$C$230:$V$329,Daten!$B$2340,$A16)=0,"–",INDEX(Daten!$C$230:$V$329,Daten!$B$2340,$A16))) | I16: =IF($A16="","",IF(INDEX(Daten!$C$125:$V$224,Daten!$B$2340,$A16)=1,"Zwischenstand – Übung läuft noch",IF(INDEX(Daten!$C$755:$V$854,Daten!$B$2340,$A16)=0,"noch nichts eingetragen","nicht bewertet"&IF(INDEX(Daten!$C$545:$V$644,Daten!$B$2340,$A16)="",""," ("&INDEX(Daten!$C$545:$V$644,Daten!$B$2340,$A16)&")"))))
A17: =IFERROR(SMALL(Daten!$C$2336:$V$2336,6),"") | B17: =IF($A17="","",INDEX(Daten!$C$4:$V$4,$A17)) | C17: =IF($A17="","",INDEX(Daten!$C$6:$V$6,$A17)) | D17: =IF($A17="","",IF(INDEX(Daten!$C$7:$V$7,$A17)=0,"",INDEX(Daten!$C$7:$V$7,$A17))) | E17: =IF($A17="","",INDEX(Daten!$C$335:$V$434,Daten!$B$2340,$A17)) | F17: =IF($A17="","",INDEX(Daten!$C$440:$V$539,Daten!$B$2340,$A17)) | G17: =IF($A17="","",IF(INDEX(Daten!$C$125:$V$224,Daten!$B$2340,$A17)=0,"",INDEX(Daten!$C$20:$V$119,Daten!$B$2340,$A17))) | H17: =IF($A17="","",IF(INDEX(Daten!$C$230:$V$329,Daten!$B$2340,$A17)=0,"–",INDEX(Daten!$C$230:$V$329,Daten!$B$2340,$A17))) | I17: =IF($A17="","",IF(INDEX(Daten!$C$125:$V$224,Daten!$B$2340,$A17)=1,"Zwischenstand – Übung läuft noch",IF(INDEX(Daten!$C$755:$V$854,Daten!$B$2340,$A17)=0,"noch nichts eingetragen","nicht bewertet"&IF(INDEX(Daten!$C$545:$V$644,Daten!$B$2340,$A17)="",""," ("&INDEX(Daten!$C$545:$V$644,Daten!$B$2340,$A17)&")"))))
A19: Übungen und Leistungen
A20: Nr. | B20: Übung | C20: Art | D20: Datum | E20: Status | F20: Punkte | G20: von max. | H20: Prozent | I20: IHK-Note | J20: zählt? | K20: Grund | L20: Bemerkung
A21: 1 | B21: =IF($A21="","",INDEX(Daten!$C$4:$V$4,$A21)) | C21: =IF($A21="","",INDEX(Daten!$C$6:$V$6,$A21)) | D21: =IF($A21="","",IF(INDEX(Daten!$C$7:$V$7,$A21)=0,"",INDEX(Daten!$C$7:$V$7,$A21))) | E21: =IF($A21="","",INDEX(Daten!$C$8:$V$8,$A21)) | F21: =IF($A21="","",IF(INDEX(Daten!$C$125:$V$224,Daten!$B$2340,$A21)=0,"",INDEX(Daten!$C$335:$V$434,Daten!$B$2340,$A21))) | G21: =IF($A21="","",IF(INDEX(Daten!$C$125:$V$224,Daten!$B$2340,$A21)=0,"",INDEX(Daten!$C$440:$V$539,Daten!$B$2340,$A21))) | H21: =IF($A21="","",IF(INDEX(Daten!$C$125:$V$224,Daten!$B$2340,$A21)=0,"",INDEX(Daten!$C$20:$V$119,Daten!$B$2340,$A21))) | I21: =IF($A21="","",IF(INDEX(Daten!$C$125:$V$224,Daten!$B$2340,$A21)=1,INDEX(Noten,MAX(1,MIN(COUNT(NGrenze),COUNT(NGrenze)+1-COUNTIF(NGrenze,"<="&$H21))))&" – "&INDEX(NText,MAX(1,MIN(COUNT(NGrenze),COUNT(NGrenze)+1-COUNTIF(NGrenze,"<="&$H21)))),IF(INDEX(Daten!$C$755:$V$854,Daten!$B$2340,$A21)=0,"","nicht bewertet"&IF(INDEX(Daten!$C$545:$V$644,Daten!$B$2340,$A21)="",""," ("&INDEX(Daten!$C$545:$V$644,Daten!$B$2340,$A21)&")")))) | J21: =IF($A21="","",IF(INDEX(Daten!$C$125:$V$224,Daten!$B$2340,$A21)=0,"–",IF(INDEX(Daten!$C$1595:$V$1694,Daten!$B$2340,$A21)=1,"ja",IF(INDEX(Daten!$C$1280:$V$1379,Daten!$B$2340,$A21)=0,"nein (Wdh.)","noch nicht (läuft)")))) | K21: =IF($A21="","",INDEX(Daten!$C$545:$V$644,Daten!$B$2340,$A21)) | L21: =IF($A21="","",INDEX(Daten!$C$1490:$V$1589,Daten!$B$2340,$A21))
A22: 2 | B22: =IF($A22="","",INDEX(Daten!$C$4:$V$4,$A22)) | C22: =IF($A22="","",INDEX(Daten!$C$6:$V$6,$A22)) | D22: =IF($A22="","",IF(INDEX(Daten!$C$7:$V$7,$A22)=0,"",INDEX(Daten!$C$7:$V$7,$A22))) | E22: =IF($A22="","",INDEX(Daten!$C$8:$V$8,$A22)) | F22: =IF($A22="","",IF(INDEX(Daten!$C$125:$V$224,Daten!$B$2340,$A22)=0,"",INDEX(Daten!$C$335:$V$434,Daten!$B$2340,$A22))) | G22: =IF($A22="","",IF(INDEX(Daten!$C$125:$V$224,Daten!$B$2340,$A22)=0,"",INDEX(Daten!$C$440:$V$539,Daten!$B$2340,$A22))) | H22: =IF($A22="","",IF(INDEX(Daten!$C$125:$V$224,Daten!$B$2340,$A22)=0,"",INDEX(Daten!$C$20:$V$119,Daten!$B$2340,$A22))) | I22: =IF($A22="","",IF(INDEX(Daten!$C$125:$V$224,Daten!$B$2340,$A22)=1,INDEX(Noten,MAX(1,MIN(COUNT(NGrenze),COUNT(NGrenze)+1-COUNTIF(NGrenze,"<="&$H22))))&" – "&INDEX(NText,MAX(1,MIN(COUNT(NGrenze),COUNT(NGrenze)+1-COUNTIF(NGrenze,"<="&$H22)))),IF(INDEX(Daten!$C$755:$V$854,Daten!$B$2340,$A22)=0,"","nicht bewertet"&IF(INDEX(Daten!$C$545:$V$644,Daten!$B$2340,$A22)="",""," ("&INDEX(Daten!$C$545:$V$644,Daten!$B$2340,$A22)&")")))) | J22: =IF($A22="","",IF(INDEX(Daten!$C$125:$V$224,Daten!$B$2340,$A22)=0,"–",IF(INDEX(Daten!$C$1595:$V$1694,Daten!$B$2340,$A22)=1,"ja",IF(INDEX(Daten!$C$1280:$V$1379,Daten!$B$2340,$A22)=0,"nein (Wdh.)","noch nicht (läuft)")))) | K22: =IF($A22="","",INDEX(Daten!$C$545:$V$644,Daten!$B$2340,$A22)) | L22: =IF($A22="","",INDEX(Daten!$C$1490:$V$1589,Daten!$B$2340,$A22))
A23: 3 | B23: =IF($A23="","",INDEX(Daten!$C$4:$V$4,$A23)) | C23: =IF($A23="","",INDEX(Daten!$C$6:$V$6,$A23)) | D23: =IF($A23="","",IF(INDEX(Daten!$C$7:$V$7,$A23)=0,"",INDEX(Daten!$C$7:$V$7,$A23))) | E23: =IF($A23="","",INDEX(Daten!$C$8:$V$8,$A23)) | F23: =IF($A23="","",IF(INDEX(Daten!$C$125:$V$224,Daten!$B$2340,$A23)=0,"",INDEX(Daten!$C$335:$V$434,Daten!$B$2340,$A23))) | G23: =IF($A23="","",IF(INDEX(Daten!$C$125:$V$224,Daten!$B$2340,$A23)=0,"",INDEX(Daten!$C$440:$V$539,Daten!$B$2340,$A23))) | H23: =IF($A23="","",IF(INDEX(Daten!$C$125:$V$224,Daten!$B$2340,$A23)=0,"",INDEX(Daten!$C$20:$V$119,Daten!$B$2340,$A23))) | I23: =IF($A23="","",IF(INDEX(Daten!$C$125:$V$224,Daten!$B$2340,$A23)=1,INDEX(Noten,MAX(1,MIN(COUNT(NGrenze),COUNT(NGrenze)+1-COUNTIF(NGrenze,"<="&$H23))))&" – "&INDEX(NText,MAX(1,MIN(COUNT(NGrenze),COUNT(NGrenze)+1-COUNTIF(NGrenze,"<="&$H23)))),IF(INDEX(Daten!$C$755:$V$854,Daten!$B$2340,$A23)=0,"","nicht bewertet"&IF(INDEX(Daten!$C$545:$V$644,Daten!$B$2340,$A23)="",""," ("&INDEX(Daten!$C$545:$V$644,Daten!$B$2340,$A23)&")")))) | J23: =IF($A23="","",IF(INDEX(Daten!$C$125:$V$224,Daten!$B$2340,$A23)=0,"–",IF(INDEX(Daten!$C$1595:$V$1694,Daten!$B$2340,$A23)=1,"ja",IF(INDEX(Daten!$C$1280:$V$1379,Daten!$B$2340,$A23)=0,"nein (Wdh.)","noch nicht (läuft)")))) | K23: =IF($A23="","",INDEX(Daten!$C$545:$V$644,Daten!$B$2340,$A23)) | L23: =IF($A23="","",INDEX(Daten!$C$1490:$V$1589,Daten!$B$2340,$A23))
A24: 4 | B24: =IF($A24="","",INDEX(Daten!$C$4:$V$4,$A24)) | C24: =IF($A24="","",INDEX(Daten!$C$6:$V$6,$A24)) | D24: =IF($A24="","",IF(INDEX(Daten!$C$7:$V$7,$A24)=0,"",INDEX(Daten!$C$7:$V$7,$A24))) | E24: =IF($A24="","",INDEX(Daten!$C$8:$V$8,$A24)) | F24: =IF($A24="","",IF(INDEX(Daten!$C$125:$V$224,Daten!$B$2340,$A24)=0,"",INDEX(Daten!$C$335:$V$434,Daten!$B$2340,$A24))) | G24: =IF($A24="","",IF(INDEX(Daten!$C$125:$V$224,Daten!$B$2340,$A24)=0,"",INDEX(Daten!$C$440:$V$539,Daten!$B$2340,$A24))) | H24: =IF($A24="","",IF(INDEX(Daten!$C$125:$V$224,Daten!$B$2340,$A24)=0,"",INDEX(Daten!$C$20:$V$119,Daten!$B$2340,$A24))) | I24: =IF($A24="","",IF(INDEX(Daten!$C$125:$V$224,Daten!$B$2340,$A24)=1,INDEX(Noten,MAX(1,MIN(COUNT(NGrenze),COUNT(NGrenze)+1-COUNTIF(NGrenze,"<="&$H24))))&" – "&INDEX(NText,MAX(1,MIN(COUNT(NGrenze),COUNT(NGrenze)+1-COUNTIF(NGrenze,"<="&$H24)))),IF(INDEX(Daten!$C$755:$V$854,Daten!$B$2340,$A24)=0,"","nicht bewertet"&IF(INDEX(Daten!$C$545:$V$644,Daten!$B$2340,$A24)="",""," ("&INDEX(Daten!$C$545:$V$644,Daten!$B$2340,$A24)&")")))) | J24: =IF($A24="","",IF(INDEX(Daten!$C$125:$V$224,Daten!$B$2340,$A24)=0,"–",IF(INDEX(Daten!$C$1595:$V$1694,Daten!$B$2340,$A24)=1,"ja",IF(INDEX(Daten!$C$1280:$V$1379,Daten!$B$2340,$A24)=0,"nein (Wdh.)","noch nicht (läuft)")))) | K24: =IF($A24="","",INDEX(Daten!$C$545:$V$644,Daten!$B$2340,$A24)) | L24: =IF($A24="","",INDEX(Daten!$C$1490:$V$1589,Daten!$B$2340,$A24))
A25: 5 | B25: =IF($A25="","",INDEX(Daten!$C$4:$V$4,$A25)) | C25: =IF($A25="","",INDEX(Daten!$C$6:$V$6,$A25)) | D25: =IF($A25="","",IF(INDEX(Daten!$C$7:$V$7,$A25)=0,"",INDEX(Daten!$C$7:$V$7,$A25))) | E25: =IF($A25="","",INDEX(Daten!$C$8:$V$8,$A25)) | F25: =IF($A25="","",IF(INDEX(Daten!$C$125:$V$224,Daten!$B$2340,$A25)=0,"",INDEX(Daten!$C$335:$V$434,Daten!$B$2340,$A25))) | G25: =IF($A25="","",IF(INDEX(Daten!$C$125:$V$224,Daten!$B$2340,$A25)=0,"",INDEX(Daten!$C$440:$V$539,Daten!$B$2340,$A25))) | H25: =IF($A25="","",IF(INDEX(Daten!$C$125:$V$224,Daten!$B$2340,$A25)=0,"",INDEX(Daten!$C$20:$V$119,Daten!$B$2340,$A25))) | I25: =IF($A25="","",IF(INDEX(Daten!$C$125:$V$224,Daten!$B$2340,$A25)=1,INDEX(Noten,MAX(1,MIN(COUNT(NGrenze),COUNT(NGrenze)+1-COUNTIF(NGrenze,"<="&$H25))))&" – "&INDEX(NText,MAX(1,MIN(COUNT(NGrenze),COUNT(NGrenze)+1-COUNTIF(NGrenze,"<="&$H25)))),IF(INDEX(Daten!$C$755:$V$854,Daten!$B$2340,$A25)=0,"","nicht bewertet"&IF(INDEX(Daten!$C$545:$V$644,Daten!$B$2340,$A25)="",""," ("&INDEX(Daten!$C$545:$V$644,Daten!$B$2340,$A25)&")")))) | J25: =IF($A25="","",IF(INDEX(Daten!$C$125:$V$224,Daten!$B$2340,$A25)=0,"–",IF(INDEX(Daten!$C$1595:$V$1694,Daten!$B$2340,$A25)=1,"ja",IF(INDEX(Daten!$C$1280:$V$1379,Daten!$B$2340,$A25)=0,"nein (Wdh.)","noch nicht (läuft)")))) | K25: =IF($A25="","",INDEX(Daten!$C$545:$V$644,Daten!$B$2340,$A25)) | L25: =IF($A25="","",INDEX(Daten!$C$1490:$V$1589,Daten!$B$2340,$A25))
A26: 6 | B26: =IF($A26="","",INDEX(Daten!$C$4:$V$4,$A26)) | C26: =IF($A26="","",INDEX(Daten!$C$6:$V$6,$A26)) | D26: =IF($A26="","",IF(INDEX(Daten!$C$7:$V$7,$A26)=0,"",INDEX(Daten!$C$7:$V$7,$A26))) | E26: =IF($A26="","",INDEX(Daten!$C$8:$V$8,$A26)) | F26: =IF($A26="","",IF(INDEX(Daten!$C$125:$V$224,Daten!$B$2340,$A26)=0,"",INDEX(Daten!$C$335:$V$434,Daten!$B$2340,$A26))) | G26: =IF($A26="","",IF(INDEX(Daten!$C$125:$V$224,Daten!$B$2340,$A26)=0,"",INDEX(Daten!$C$440:$V$539,Daten!$B$2340,$A26))) | H26: =IF($A26="","",IF(INDEX(Daten!$C$125:$V$224,Daten!$B$2340,$A26)=0,"",INDEX(Daten!$C$20:$V$119,Daten!$B$2340,$A26))) | I26: =IF($A26="","",IF(INDEX(Daten!$C$125:$V$224,Daten!$B$2340,$A26)=1,INDEX(Noten,MAX(1,MIN(COUNT(NGrenze),COUNT(NGrenze)+1-COUNTIF(NGrenze,"<="&$H26))))&" – "&INDEX(NText,MAX(1,MIN(COUNT(NGrenze),COUNT(NGrenze)+1-COUNTIF(NGrenze,"<="&$H26)))),IF(INDEX(Daten!$C$755:$V$854,Daten!$B$2340,$A26)=0,"","nicht bewertet"&IF(INDEX(Daten!$C$545:$V$644,Daten!$B$2340,$A26)="",""," ("&INDEX(Daten!$C$545:$V$644,Daten!$B$2340,$A26)&")")))) | J26: =IF($A26="","",IF(INDEX(Daten!$C$125:$V$224,Daten!$B$2340,$A26)=0,"–",IF(INDEX(Daten!$C$1595:$V$1694,Daten!$B$2340,$A26)=1,"ja",IF(INDEX(Daten!$C$1280:$V$1379,Daten!$B$2340,$A26)=0,"nein (Wdh.)","noch nicht (läuft)")))) | K26: =IF($A26="","",INDEX(Daten!$C$545:$V$644,Daten!$B$2340,$A26)) | L26: =IF($A26="","",INDEX(Daten!$C$1490:$V$1589,Daten!$B$2340,$A26))
A27: 7 | B27: =IF($A27="","",INDEX(Daten!$C$4:$V$4,$A27)) | C27: =IF($A27="","",INDEX(Daten!$C$6:$V$6,$A27)) | D27: =IF($A27="","",IF(INDEX(Daten!$C$7:$V$7,$A27)=0,"",INDEX(Daten!$C$7:$V$7,$A27))) | E27: =IF($A27="","",INDEX(Daten!$C$8:$V$8,$A27)) | F27: =IF($A27="","",IF(INDEX(Daten!$C$125:$V$224,Daten!$B$2340,$A27)=0,"",INDEX(Daten!$C$335:$V$434,Daten!$B$2340,$A27))) | G27: =IF($A27="","",IF(INDEX(Daten!$C$125:$V$224,Daten!$B$2340,$A27)=0,"",INDEX(Daten!$C$440:$V$539,Daten!$B$2340,$A27))) | H27: =IF($A27="","",IF(INDEX(Daten!$C$125:$V$224,Daten!$B$2340,$A27)=0,"",INDEX(Daten!$C$20:$V$119,Daten!$B$2340,$A27))) | I27: =IF($A27="","",IF(INDEX(Daten!$C$125:$V$224,Daten!$B$2340,$A27)=1,INDEX(Noten,MAX(1,MIN(COUNT(NGrenze),COUNT(NGrenze)+1-COUNTIF(NGrenze,"<="&$H27))))&" – "&INDEX(NText,MAX(1,MIN(COUNT(NGrenze),COUNT(NGrenze)+1-COUNTIF(NGrenze,"<="&$H27)))),IF(INDEX(Daten!$C$755:$V$854,Daten!$B$2340,$A27)=0,"","nicht bewertet"&IF(INDEX(Daten!$C$545:$V$644,Daten!$B$2340,$A27)="",""," ("&INDEX(Daten!$C$545:$V$644,Daten!$B$2340,$A27)&")")))) | J27: =IF($A27="","",IF(INDEX(Daten!$C$125:$V$224,Daten!$B$2340,$A27)=0,"–",IF(INDEX(Daten!$C$1595:$V$1694,Daten!$B$2340,$A27)=1,"ja",IF(INDEX(Daten!$C$1280:$V$1379,Daten!$B$2340,$A27)=0,"nein (Wdh.)","noch nicht (läuft)")))) | K27: =IF($A27="","",INDEX(Daten!$C$545:$V$644,Daten!$B$2340,$A27)) | L27: =IF($A27="","",INDEX(Daten!$C$1490:$V$1589,Daten!$B$2340,$A27))
A28: 8 | B28: =IF($A28="","",INDEX(Daten!$C$4:$V$4,$A28)) | C28: =IF($A28="","",INDEX(Daten!$C$6:$V$6,$A28)) | D28: =IF($A28="","",IF(INDEX(Daten!$C$7:$V$7,$A28)=0,"",INDEX(Daten!$C$7:$V$7,$A28))) | E28: =IF($A28="","",INDEX(Daten!$C$8:$V$8,$A28)) | F28: =IF($A28="","",IF(INDEX(Daten!$C$125:$V$224,Daten!$B$2340,$A28)=0,"",INDEX(Daten!$C$335:$V$434,Daten!$B$2340,$A28))) | G28: =IF($A28="","",IF(INDEX(Daten!$C$125:$V$224,Daten!$B$2340,$A28)=0,"",INDEX(Daten!$C$440:$V$539,Daten!$B$2340,$A28))) | H28: =IF($A28="","",IF(INDEX(Daten!$C$125:$V$224,Daten!$B$2340,$A28)=0,"",INDEX(Daten!$C$20:$V$119,Daten!$B$2340,$A28))) | I28: =IF($A28="","",IF(INDEX(Daten!$C$125:$V$224,Daten!$B$2340,$A28)=1,INDEX(Noten,MAX(1,MIN(COUNT(NGrenze),COUNT(NGrenze)+1-COUNTIF(NGrenze,"<="&$H28))))&" – "&INDEX(NText,MAX(1,MIN(COUNT(NGrenze),COUNT(NGrenze)+1-COUNTIF(NGrenze,"<="&$H28)))),IF(INDEX(Daten!$C$755:$V$854,Daten!$B$2340,$A28)=0,"","nicht bewertet"&IF(INDEX(Daten!$C$545:$V$644,Daten!$B$2340,$A28)="",""," ("&INDEX(Daten!$C$545:$V$644,Daten!$B$2340,$A28)&")")))) | J28: =IF($A28="","",IF(INDEX(Daten!$C$125:$V$224,Daten!$B$2340,$A28)=0,"–",IF(INDEX(Daten!$C$1595:$V$1694,Daten!$B$2340,$A28)=1,"ja",IF(INDEX(Daten!$C$1280:$V$1379,Daten!$B$2340,$A28)=0,"nein (Wdh.)","noch nicht (läuft)")))) | K28: =IF($A28="","",INDEX(Daten!$C$545:$V$644,Daten!$B$2340,$A28)) | L28: =IF($A28="","",INDEX(Daten!$C$1490:$V$1589,Daten!$B$2340,$A28))
A29: 9 | B29: =IF($A29="","",INDEX(Daten!$C$4:$V$4,$A29)) | C29: =IF($A29="","",INDEX(Daten!$C$6:$V$6,$A29)) | D29: =IF($A29="","",IF(INDEX(Daten!$C$7:$V$7,$A29)=0,"",INDEX(Daten!$C$7:$V$7,$A29))) | E29: =IF($A29="","",INDEX(Daten!$C$8:$V$8,$A29)) | F29: =IF($A29="","",IF(INDEX(Daten!$C$125:$V$224,Daten!$B$2340,$A29)=0,"",INDEX(Daten!$C$335:$V$434,Daten!$B$2340,$A29))) | G29: =IF($A29="","",IF(INDEX(Daten!$C$125:$V$224,Daten!$B$2340,$A29)=0,"",INDEX(Daten!$C$440:$V$539,Daten!$B$2340,$A29))) | H29: =IF($A29="","",IF(INDEX(Daten!$C$125:$V$224,Daten!$B$2340,$A29)=0,"",INDEX(Daten!$C$20:$V$119,Daten!$B$2340,$A29))) | I29: =IF($A29="","",IF(INDEX(Daten!$C$125:$V$224,Daten!$B$2340,$A29)=1,INDEX(Noten,MAX(1,MIN(COUNT(NGrenze),COUNT(NGrenze)+1-COUNTIF(NGrenze,"<="&$H29))))&" – "&INDEX(NText,MAX(1,MIN(COUNT(NGrenze),COUNT(NGrenze)+1-COUNTIF(NGrenze,"<="&$H29)))),IF(INDEX(Daten!$C$755:$V$854,Daten!$B$2340,$A29)=0,"","nicht bewertet"&IF(INDEX(Daten!$C$545:$V$644,Daten!$B$2340,$A29)="",""," ("&INDEX(Daten!$C$545:$V$644,Daten!$B$2340,$A29)&")")))) | J29: =IF($A29="","",IF(INDEX(Daten!$C$125:$V$224,Daten!$B$2340,$A29)=0,"–",IF(INDEX(Daten!$C$1595:$V$1694,Daten!$B$2340,$A29)=1,"ja",IF(INDEX(Daten!$C$1280:$V$1379,Daten!$B$2340,$A29)=0,"nein (Wdh.)","noch nicht (läuft)")))) | K29: =IF($A29="","",INDEX(Daten!$C$545:$V$644,Daten!$B$2340,$A29)) | L29: =IF($A29="","",INDEX(Daten!$C$1490:$V$1589,Daten!$B$2340,$A29))
A30: 10 | B30: =IF($A30="","",INDEX(Daten!$C$4:$V$4,$A30)) | C30: =IF($A30="","",INDEX(Daten!$C$6:$V$6,$A30)) | D30: =IF($A30="","",IF(INDEX(Daten!$C$7:$V$7,$A30)=0,"",INDEX(Daten!$C$7:$V$7,$A30))) | E30: =IF($A30="","",INDEX(Daten!$C$8:$V$8,$A30)) | F30: =IF($A30="","",IF(INDEX(Daten!$C$125:$V$224,Daten!$B$2340,$A30)=0,"",INDEX(Daten!$C$335:$V$434,Daten!$B$2340,$A30))) | G30: =IF($A30="","",IF(INDEX(Daten!$C$125:$V$224,Daten!$B$2340,$A30)=0,"",INDEX(Daten!$C$440:$V$539,Daten!$B$2340,$A30))) | H30: =IF($A30="","",IF(INDEX(Daten!$C$125:$V$224,Daten!$B$2340,$A30)=0,"",INDEX(Daten!$C$20:$V$119,Daten!$B$2340,$A30))) | I30: =IF($A30="","",IF(INDEX(Daten!$C$125:$V$224,Daten!$B$2340,$A30)=1,INDEX(Noten,MAX(1,MIN(COUNT(NGrenze),COUNT(NGrenze)+1-COUNTIF(NGrenze,"<="&$H30))))&" – "&INDEX(NText,MAX(1,MIN(COUNT(NGrenze),COUNT(NGrenze)+1-COUNTIF(NGrenze,"<="&$H30)))),IF(INDEX(Daten!$C$755:$V$854,Daten!$B$2340,$A30)=0,"","nicht bewertet"&IF(INDEX(Daten!$C$545:$V$644,Daten!$B$2340,$A30)="",""," ("&INDEX(Daten!$C$545:$V$644,Daten!$B$2340,$A30)&")")))) | J30: =IF($A30="","",IF(INDEX(Daten!$C$125:$V$224,Daten!$B$2340,$A30)=0,"–",IF(INDEX(Daten!$C$1595:$V$1694,Daten!$B$2340,$A30)=1,"ja",IF(INDEX(Daten!$C$1280:$V$1379,Daten!$B$2340,$A30)=0,"nein (Wdh.)","noch nicht (läuft)")))) | K30: =IF($A30="","",INDEX(Daten!$C$545:$V$644,Daten!$B$2340,$A30)) | L30: =IF($A30="","",INDEX(Daten!$C$1490:$V$1589,Daten!$B$2340,$A30))
A31: 11 | B31: =IF($A31="","",INDEX(Daten!$C$4:$V$4,$A31)) | C31: =IF($A31="","",INDEX(Daten!$C$6:$V$6,$A31)) | D31: =IF($A31="","",IF(INDEX(Daten!$C$7:$V$7,$A31)=0,"",INDEX(Daten!$C$7:$V$7,$A31))) | E31: =IF($A31="","",INDEX(Daten!$C$8:$V$8,$A31)) | F31: =IF($A31="","",IF(INDEX(Daten!$C$125:$V$224,Daten!$B$2340,$A31)=0,"",INDEX(Daten!$C$335:$V$434,Daten!$B$2340,$A31))) | G31: =IF($A31="","",IF(INDEX(Daten!$C$125:$V$224,Daten!$B$2340,$A31)=0,"",INDEX(Daten!$C$440:$V$539,Daten!$B$2340,$A31))) | H31: =IF($A31="","",IF(INDEX(Daten!$C$125:$V$224,Daten!$B$2340,$A31)=0,"",INDEX(Daten!$C$20:$V$119,Daten!$B$2340,$A31))) | I31: =IF($A31="","",IF(INDEX(Daten!$C$125:$V$224,Daten!$B$2340,$A31)=1,INDEX(Noten,MAX(1,MIN(COUNT(NGrenze),COUNT(NGrenze)+1-COUNTIF(NGrenze,"<="&$H31))))&" – "&INDEX(NText,MAX(1,MIN(COUNT(NGrenze),COUNT(NGrenze)+1-COUNTIF(NGrenze,"<="&$H31)))),IF(INDEX(Daten!$C$755:$V$854,Daten!$B$2340,$A31)=0,"","nicht bewertet"&IF(INDEX(Daten!$C$545:$V$644,Daten!$B$2340,$A31)="",""," ("&INDEX(Daten!$C$545:$V$644,Daten!$B$2340,$A31)&")")))) | J31: =IF($A31="","",IF(INDEX(Daten!$C$125:$V$224,Daten!$B$2340,$A31)=0,"–",IF(INDEX(Daten!$C$1595:$V$1694,Daten!$B$2340,$A31)=1,"ja",IF(INDEX(Daten!$C$1280:$V$1379,Daten!$B$2340,$A31)=0,"nein (Wdh.)","noch nicht (läuft)")))) | K31: =IF($A31="","",INDEX(Daten!$C$545:$V$644,Daten!$B$2340,$A31)) | L31: =IF($A31="","",INDEX(Daten!$C$1490:$V$1589,Daten!$B$2340,$A31))
A32: 12 | B32: =IF($A32="","",INDEX(Daten!$C$4:$V$4,$A32)) | C32: =IF($A32="","",INDEX(Daten!$C$6:$V$6,$A32)) | D32: =IF($A32="","",IF(INDEX(Daten!$C$7:$V$7,$A32)=0,"",INDEX(Daten!$C$7:$V$7,$A32))) | E32: =IF($A32="","",INDEX(Daten!$C$8:$V$8,$A32)) | F32: =IF($A32="","",IF(INDEX(Daten!$C$125:$V$224,Daten!$B$2340,$A32)=0,"",INDEX(Daten!$C$335:$V$434,Daten!$B$2340,$A32))) | G32: =IF($A32="","",IF(INDEX(Daten!$C$125:$V$224,Daten!$B$2340,$A32)=0,"",INDEX(Daten!$C$440:$V$539,Daten!$B$2340,$A32))) | H32: =IF($A32="","",IF(INDEX(Daten!$C$125:$V$224,Daten!$B$2340,$A32)=0,"",INDEX(Daten!$C$20:$V$119,Daten!$B$2340,$A32))) | I32: =IF($A32="","",IF(INDEX(Daten!$C$125:$V$224,Daten!$B$2340,$A32)=1,INDEX(Noten,MAX(1,MIN(COUNT(NGrenze),COUNT(NGrenze)+1-COUNTIF(NGrenze,"<="&$H32))))&" – "&INDEX(NText,MAX(1,MIN(COUNT(NGrenze),COUNT(NGrenze)+1-COUNTIF(NGrenze,"<="&$H32)))),IF(INDEX(Daten!$C$755:$V$854,Daten!$B$2340,$A32)=0,"","nicht bewertet"&IF(INDEX(Daten!$C$545:$V$644,Daten!$B$2340,$A32)="",""," ("&INDEX(Daten!$C$545:$V$644,Daten!$B$2340,$A32)&")")))) | J32: =IF($A32="","",IF(INDEX(Daten!$C$125:$V$224,Daten!$B$2340,$A32)=0,"–",IF(INDEX(Daten!$C$1595:$V$1694,Daten!$B$2340,$A32)=1,"ja",IF(INDEX(Daten!$C$1280:$V$1379,Daten!$B$2340,$A32)=0,"nein (Wdh.)","noch nicht (läuft)")))) | K32: =IF($A32="","",INDEX(Daten!$C$545:$V$644,Daten!$B$2340,$A32)) | L32: =IF($A32="","",INDEX(Daten!$C$1490:$V$1589,Daten!$B$2340,$A32))
... A40: 20 | B40: =IF($A40="","",INDEX(Daten!$C$4:$V$4,$A40)) | C40: =IF($A40="","",INDEX(Daten!$C$6:$V$6,$A40)) | D40: =IF($A40="","",IF(INDEX(Daten!$C$7:$V$7,$A40)=0,"",INDEX(Daten!$C$7:$V$7,$A40))) | E40: =IF($A40="","",INDEX(Daten!$C$8:$V$8,$A40)) | F40: =IF($A40="","",IF(INDEX(Daten!$C$125:$V$224,Daten!$B$2340,$A40)=0,"",INDEX(Daten!$C$335:$V$434,Daten!$B$2340,$A40))) | G40: =IF($A40="","",IF(INDEX(Daten!$C$125:$V$224,Daten!$B$2340,$A40)=0,"",INDEX(Daten!$C$440:$V$539,Daten!$B$2340,$A40))) | H40: =IF($A40="","",IF(INDEX(Daten!$C$125:$V$224,Daten!$B$2340,$A40)=0,"",INDEX(Daten!$C$20:$V$119,Daten!$B$2340,$A40))) | I40: =IF($A40="","",IF(INDEX(Daten!$C$125:$V$224,Daten!$B$2340,$A40)=1,INDEX(Noten,MAX(1,MIN(COUNT(NGrenze),COUNT(NGrenze)+1-COUNTIF(NGrenze,"<="&$H40))))&" – "&INDEX(NText,MAX(1,MIN(COUNT(NGrenze),COUNT(NGrenze)+1-COUNTIF(NGrenze,"<="&$H40)))),IF(INDEX(Daten!$C$755:$V$854,Daten!$B$2340,$A40)=0,"","nicht bewertet"&IF(INDEX(Daten!$C$545:$V$644,Daten!$B$2340,$A40)="",""," ("&INDEX(Daten!$C$545:$V$644,Daten!$B$2340,$A40)&")")))) | J40: =IF($A40="","",IF(INDEX(Daten!$C$125:$V$224,Daten!$B$2340,$A40)=0,"–",IF(INDEX(Daten!$C$1595:$V$1694,Daten!$B$2340,$A40)=1,"ja",IF(INDEX(Daten!$C$1280:$V$1379,Daten!$B$2340,$A40)=0,"nein (Wdh.)","noch nicht (läuft)")))) | K40: =IF($A40="","",INDEX(Daten!$C$545:$V$644,Daten!$B$2340,$A40)) | L40: =IF($A40="","",INDEX(Daten!$C$1490:$V$1589,Daten!$B$2340,$A40))
A42: Halbjahresauswertung für das Gespräch
A43: HJ | B43: Zeitraum ab Ausbildungsstart | C43: Übungen | D43: Praxis % | E43: Praxis Note | F43: Theorie % | G43: Theorie Note | H43: Gesamt % | I43: Gesamt Note | J43: Hinweis
A44: 1 | B44: ="Monat "&(1-1)*6+1&" bis "&1*6 | C44: =IF(Daten!$B$2340=0,"",INDEX(Daten!$C$1704:$J$1803,Daten!$B$2340,1)) | D44: =IF(Daten!$B$2340=0,"",INDEX(Daten!$C$2019:$J$2118,Daten!$B$2340,1)) | E44: =IF(NOT(ISNUMBER(D44)),"",INDEX(Noten,MAX(1,MIN(COUNT(NGrenze),COUNT(NGrenze)+1-COUNTIF(NGrenze,"<="&D44))))&" – "&INDEX(NText,MAX(1,MIN(COUNT(NGrenze),COUNT(NGrenze)+1-COUNTIF(NGrenze,"<="&D44))))) | F44: =IF(Daten!$B$2340=0,"",INDEX(Daten!$C$2124:$J$2223,Daten!$B$2340,1)) | G44: =IF(NOT(ISNUMBER(F44)),"",INDEX(Noten,MAX(1,MIN(COUNT(NGrenze),COUNT(NGrenze)+1-COUNTIF(NGrenze,"<="&F44))))&" – "&INDEX(NText,MAX(1,MIN(COUNT(NGrenze),COUNT(NGrenze)+1-COUNTIF(NGrenze,"<="&F44))))) | H44: =IF(Daten!$B$2340=0,"",INDEX(Daten!$C$2229:$J$2328,Daten!$B$2340,1)) | I44: =IF(NOT(ISNUMBER(H44)),"",INDEX(Noten,MAX(1,MIN(COUNT(NGrenze),COUNT(NGrenze)+1-COUNTIF(NGrenze,"<="&H44))))&" – "&INDEX(NText,MAX(1,MIN(COUNT(NGrenze),COUNT(NGrenze)+1-COUNTIF(NGrenze,"<="&H44))))) | J44: =IF(OR(Daten!$B$2340=0,C44=""),"",IF(C44=0,"keine Bewertung in diesem Halbjahr",IF(C44<SchwelleDB,"wenig Datenbasis ("&C44&" Übung"&IF(C44=1,"","en")&")","")))
A45: 2 | B45: ="Monat "&(2-1)*6+1&" bis "&2*6 | C45: =IF(Daten!$B$2340=0,"",INDEX(Daten!$C$1704:$J$1803,Daten!$B$2340,2)) | D45: =IF(Daten!$B$2340=0,"",INDEX(Daten!$C$2019:$J$2118,Daten!$B$2340,2)) | E45: =IF(NOT(ISNUMBER(D45)),"",INDEX(Noten,MAX(1,MIN(COUNT(NGrenze),COUNT(NGrenze)+1-COUNTIF(NGrenze,"<="&D45))))&" – "&INDEX(NText,MAX(1,MIN(COUNT(NGrenze),COUNT(NGrenze)+1-COUNTIF(NGrenze,"<="&D45))))) | F45: =IF(Daten!$B$2340=0,"",INDEX(Daten!$C$2124:$J$2223,Daten!$B$2340,2)) | G45: =IF(NOT(ISNUMBER(F45)),"",INDEX(Noten,MAX(1,MIN(COUNT(NGrenze),COUNT(NGrenze)+1-COUNTIF(NGrenze,"<="&F45))))&" – "&INDEX(NText,MAX(1,MIN(COUNT(NGrenze),COUNT(NGrenze)+1-COUNTIF(NGrenze,"<="&F45))))) | H45: =IF(Daten!$B$2340=0,"",INDEX(Daten!$C$2229:$J$2328,Daten!$B$2340,2)) | I45: =IF(NOT(ISNUMBER(H45)),"",INDEX(Noten,MAX(1,MIN(COUNT(NGrenze),COUNT(NGrenze)+1-COUNTIF(NGrenze,"<="&H45))))&" – "&INDEX(NText,MAX(1,MIN(COUNT(NGrenze),COUNT(NGrenze)+1-COUNTIF(NGrenze,"<="&H45))))) | J45: =IF(OR(Daten!$B$2340=0,C45=""),"",IF(C45=0,"keine Bewertung in diesem Halbjahr",IF(C45<SchwelleDB,"wenig Datenbasis ("&C45&" Übung"&IF(C45=1,"","en")&")","")))
A46: 3 | B46: ="Monat "&(3-1)*6+1&" bis "&3*6 | C46: =IF(Daten!$B$2340=0,"",INDEX(Daten!$C$1704:$J$1803,Daten!$B$2340,3)) | D46: =IF(Daten!$B$2340=0,"",INDEX(Daten!$C$2019:$J$2118,Daten!$B$2340,3)) | E46: =IF(NOT(ISNUMBER(D46)),"",INDEX(Noten,MAX(1,MIN(COUNT(NGrenze),COUNT(NGrenze)+1-COUNTIF(NGrenze,"<="&D46))))&" – "&INDEX(NText,MAX(1,MIN(COUNT(NGrenze),COUNT(NGrenze)+1-COUNTIF(NGrenze,"<="&D46))))) | F46: =IF(Daten!$B$2340=0,"",INDEX(Daten!$C$2124:$J$2223,Daten!$B$2340,3)) | G46: =IF(NOT(ISNUMBER(F46)),"",INDEX(Noten,MAX(1,MIN(COUNT(NGrenze),COUNT(NGrenze)+1-COUNTIF(NGrenze,"<="&F46))))&" – "&INDEX(NText,MAX(1,MIN(COUNT(NGrenze),COUNT(NGrenze)+1-COUNTIF(NGrenze,"<="&F46))))) | H46: =IF(Daten!$B$2340=0,"",INDEX(Daten!$C$2229:$J$2328,Daten!$B$2340,3)) | I46: =IF(NOT(ISNUMBER(H46)),"",INDEX(Noten,MAX(1,MIN(COUNT(NGrenze),COUNT(NGrenze)+1-COUNTIF(NGrenze,"<="&H46))))&" – "&INDEX(NText,MAX(1,MIN(COUNT(NGrenze),COUNT(NGrenze)+1-COUNTIF(NGrenze,"<="&H46))))) | J46: =IF(OR(Daten!$B$2340=0,C46=""),"",IF(C46=0,"keine Bewertung in diesem Halbjahr",IF(C46<SchwelleDB,"wenig Datenbasis ("&C46&" Übung"&IF(C46=1,"","en")&")","")))
A47: 4 | B47: ="Monat "&(4-1)*6+1&" bis "&4*6 | C47: =IF(Daten!$B$2340=0,"",INDEX(Daten!$C$1704:$J$1803,Daten!$B$2340,4)) | D47: =IF(Daten!$B$2340=0,"",INDEX(Daten!$C$2019:$J$2118,Daten!$B$2340,4)) | E47: =IF(NOT(ISNUMBER(D47)),"",INDEX(Noten,MAX(1,MIN(COUNT(NGrenze),COUNT(NGrenze)+1-COUNTIF(NGrenze,"<="&D47))))&" – "&INDEX(NText,MAX(1,MIN(COUNT(NGrenze),COUNT(NGrenze)+1-COUNTIF(NGrenze,"<="&D47))))) | F47: =IF(Daten!$B$2340=0,"",INDEX(Daten!$C$2124:$J$2223,Daten!$B$2340,4)) | G47: =IF(NOT(ISNUMBER(F47)),"",INDEX(Noten,MAX(1,MIN(COUNT(NGrenze),COUNT(NGrenze)+1-COUNTIF(NGrenze,"<="&F47))))&" – "&INDEX(NText,MAX(1,MIN(COUNT(NGrenze),COUNT(NGrenze)+1-COUNTIF(NGrenze,"<="&F47))))) | H47: =IF(Daten!$B$2340=0,"",INDEX(Daten!$C$2229:$J$2328,Daten!$B$2340,4)) | I47: =IF(NOT(ISNUMBER(H47)),"",INDEX(Noten,MAX(1,MIN(COUNT(NGrenze),COUNT(NGrenze)+1-COUNTIF(NGrenze,"<="&H47))))&" – "&INDEX(NText,MAX(1,MIN(COUNT(NGrenze),COUNT(NGrenze)+1-COUNTIF(NGrenze,"<="&H47))))) | J47: =IF(OR(Daten!$B$2340=0,C47=""),"",IF(C47=0,"keine Bewertung in diesem Halbjahr",IF(C47<SchwelleDB,"wenig Datenbasis ("&C47&" Übung"&IF(C47=1,"","en")&")","")))
A48: 5 | B48: ="Monat "&(5-1)*6+1&" bis "&5*6 | C48: =IF(Daten!$B$2340=0,"",INDEX(Daten!$C$1704:$J$1803,Daten!$B$2340,5)) | D48: =IF(Daten!$B$2340=0,"",INDEX(Daten!$C$2019:$J$2118,Daten!$B$2340,5)) | E48: =IF(NOT(ISNUMBER(D48)),"",INDEX(Noten,MAX(1,MIN(COUNT(NGrenze),COUNT(NGrenze)+1-COUNTIF(NGrenze,"<="&D48))))&" – "&INDEX(NText,MAX(1,MIN(COUNT(NGrenze),COUNT(NGrenze)+1-COUNTIF(NGrenze,"<="&D48))))) | F48: =IF(Daten!$B$2340=0,"",INDEX(Daten!$C$2124:$J$2223,Daten!$B$2340,5)) | G48: =IF(NOT(ISNUMBER(F48)),"",INDEX(Noten,MAX(1,MIN(COUNT(NGrenze),COUNT(NGrenze)+1-COUNTIF(NGrenze,"<="&F48))))&" – "&INDEX(NText,MAX(1,MIN(COUNT(NGrenze),COUNT(NGrenze)+1-COUNTIF(NGrenze,"<="&F48))))) | H48: =IF(Daten!$B$2340=0,"",INDEX(Daten!$C$2229:$J$2328,Daten!$B$2340,5)) | I48: =IF(NOT(ISNUMBER(H48)),"",INDEX(Noten,MAX(1,MIN(COUNT(NGrenze),COUNT(NGrenze)+1-COUNTIF(NGrenze,"<="&H48))))&" – "&INDEX(NText,MAX(1,MIN(COUNT(NGrenze),COUNT(NGrenze)+1-COUNTIF(NGrenze,"<="&H48))))) | J48: =IF(OR(Daten!$B$2340=0,C48=""),"",IF(C48=0,"keine Bewertung in diesem Halbjahr",IF(C48<SchwelleDB,"wenig Datenbasis ("&C48&" Übung"&IF(C48=1,"","en")&")","")))
A49: 6 | B49: ="Monat "&(6-1)*6+1&" bis "&6*6 | C49: =IF(Daten!$B$2340=0,"",INDEX(Daten!$C$1704:$J$1803,Daten!$B$2340,6)) | D49: =IF(Daten!$B$2340=0,"",INDEX(Daten!$C$2019:$J$2118,Daten!$B$2340,6)) | E49: =IF(NOT(ISNUMBER(D49)),"",INDEX(Noten,MAX(1,MIN(COUNT(NGrenze),COUNT(NGrenze)+1-COUNTIF(NGrenze,"<="&D49))))&" – "&INDEX(NText,MAX(1,MIN(COUNT(NGrenze),COUNT(NGrenze)+1-COUNTIF(NGrenze,"<="&D49))))) | F49: =IF(Daten!$B$2340=0,"",INDEX(Daten!$C$2124:$J$2223,Daten!$B$2340,6)) | G49: =IF(NOT(ISNUMBER(F49)),"",INDEX(Noten,MAX(1,MIN(COUNT(NGrenze),COUNT(NGrenze)+1-COUNTIF(NGrenze,"<="&F49))))&" – "&INDEX(NText,MAX(1,MIN(COUNT(NGrenze),COUNT(NGrenze)+1-COUNTIF(NGrenze,"<="&F49))))) | H49: =IF(Daten!$B$2340=0,"",INDEX(Daten!$C$2229:$J$2328,Daten!$B$2340,6)) | I49: =IF(NOT(ISNUMBER(H49)),"",INDEX(Noten,MAX(1,MIN(COUNT(NGrenze),COUNT(NGrenze)+1-COUNTIF(NGrenze,"<="&H49))))&" – "&INDEX(NText,MAX(1,MIN(COUNT(NGrenze),COUNT(NGrenze)+1-COUNTIF(NGrenze,"<="&H49))))) | J49: =IF(OR(Daten!$B$2340=0,C49=""),"",IF(C49=0,"keine Bewertung in diesem Halbjahr",IF(C49<SchwelleDB,"wenig Datenbasis ("&C49&" Übung"&IF(C49=1,"","en")&")","")))
A50: 7 | B50: ="Monat "&(7-1)*6+1&" bis "&7*6 | C50: =IF(Daten!$B$2340=0,"",INDEX(Daten!$C$1704:$J$1803,Daten!$B$2340,7)) | D50: =IF(Daten!$B$2340=0,"",INDEX(Daten!$C$2019:$J$2118,Daten!$B$2340,7)) | E50: =IF(NOT(ISNUMBER(D50)),"",INDEX(Noten,MAX(1,MIN(COUNT(NGrenze),COUNT(NGrenze)+1-COUNTIF(NGrenze,"<="&D50))))&" – "&INDEX(NText,MAX(1,MIN(COUNT(NGrenze),COUNT(NGrenze)+1-COUNTIF(NGrenze,"<="&D50))))) | F50: =IF(Daten!$B$2340=0,"",INDEX(Daten!$C$2124:$J$2223,Daten!$B$2340,7)) | G50: =IF(NOT(ISNUMBER(F50)),"",INDEX(Noten,MAX(1,MIN(COUNT(NGrenze),COUNT(NGrenze)+1-COUNTIF(NGrenze,"<="&F50))))&" – "&INDEX(NText,MAX(1,MIN(COUNT(NGrenze),COUNT(NGrenze)+1-COUNTIF(NGrenze,"<="&F50))))) | H50: =IF(Daten!$B$2340=0,"",INDEX(Daten!$C$2229:$J$2328,Daten!$B$2340,7)) | I50: =IF(NOT(ISNUMBER(H50)),"",INDEX(Noten,MAX(1,MIN(COUNT(NGrenze),COUNT(NGrenze)+1-COUNTIF(NGrenze,"<="&H50))))&" – "&INDEX(NText,MAX(1,MIN(COUNT(NGrenze),COUNT(NGrenze)+1-COUNTIF(NGrenze,"<="&H50))))) | J50: =IF(OR(Daten!$B$2340=0,C50=""),"",IF(C50=0,"keine Bewertung in diesem Halbjahr",IF(C50<SchwelleDB,"wenig Datenbasis ("&C50&" Übung"&IF(C50=1,"","en")&")","")))
A51: 8 | B51: ="Monat "&(8-1)*6+1&" bis "&8*6 | C51: =IF(Daten!$B$2340=0,"",INDEX(Daten!$C$1704:$J$1803,Daten!$B$2340,8)) | D51: =IF(Daten!$B$2340=0,"",INDEX(Daten!$C$2019:$J$2118,Daten!$B$2340,8)) | E51: =IF(NOT(ISNUMBER(D51)),"",INDEX(Noten,MAX(1,MIN(COUNT(NGrenze),COUNT(NGrenze)+1-COUNTIF(NGrenze,"<="&D51))))&" – "&INDEX(NText,MAX(1,MIN(COUNT(NGrenze),COUNT(NGrenze)+1-COUNTIF(NGrenze,"<="&D51))))) | F51: =IF(Daten!$B$2340=0,"",INDEX(Daten!$C$2124:$J$2223,Daten!$B$2340,8)) | G51: =IF(NOT(ISNUMBER(F51)),"",INDEX(Noten,MAX(1,MIN(COUNT(NGrenze),COUNT(NGrenze)+1-COUNTIF(NGrenze,"<="&F51))))&" – "&INDEX(NText,MAX(1,MIN(COUNT(NGrenze),COUNT(NGrenze)+1-COUNTIF(NGrenze,"<="&F51))))) | H51: =IF(Daten!$B$2340=0,"",INDEX(Daten!$C$2229:$J$2328,Daten!$B$2340,8)) | I51: =IF(NOT(ISNUMBER(H51)),"",INDEX(Noten,MAX(1,MIN(COUNT(NGrenze),COUNT(NGrenze)+1-COUNTIF(NGrenze,"<="&H51))))&" – "&INDEX(NText,MAX(1,MIN(COUNT(NGrenze),COUNT(NGrenze)+1-COUNTIF(NGrenze,"<="&H51))))) | J51: =IF(OR(Daten!$B$2340=0,C51=""),"",IF(C51=0,"keine Bewertung in diesem Halbjahr",IF(C51<SchwelleDB,"wenig Datenbasis ("&C51&" Übung"&IF(C51=1,"","en")&")","")))
...

Sheet Gesprächsseite
A1: « Zurück zur Startseite | E1: Diese Seite ist für den Ausdruck gedacht: A4 hochkant, eine Seite.
A2: Farben: gelb = hier eintragen · grau-blau = rechnet die Datei selbst · „n.b.“ = nicht bewertet
A3: Beurteilungsgespräch
A4: ="Halbjahresgespräch · Halbjahr "&Daten!$B$2343&" · Stand "&RIGHT("0"&DAY(TODAY()),2)&"."&RIGHT("0"&MONTH(TODAY()),2)&"."&YEAR(TODAY())
A6: Azubi | C6: Berger, Lukas | E6: Halbjahr | F6: 4 | G6: =IF(Daten!$B$2342=0,"bitte Azubi wählen","")
B8: Name, Vorname | D8: Ausbildungsberuf
B9: =IF(Daten!$B$2342=0,"–",INDEX('Stammdaten'!$J$6:$J$105,Daten!$B$2342)) | D9: =IF(Daten!$B$2342=0,"–",INDEX('Stammdaten'!$D$6:$D$105,Daten!$B$2342))
B10: Jahrgang | C10: Ausbildungsstart | D10: Lehrjahr | E10: Halbjahr | F10: Status
B11: =IF(Daten!$B$2342=0,"–",INDEX('Stammdaten'!$E$6:$E$105,Daten!$B$2342)) | C11: =IF(Daten!$B$2342=0,"–",INDEX('Stammdaten'!$F$6:$F$105,Daten!$B$2342)) | D11: =IF(Daten!$B$2342=0,"–",INDEX('Stammdaten'!$H$6:$H$105,Daten!$B$2342)) | E11: =IF(Daten!$B$2342=0,"–",Daten!$B$2343) | F11: =IF(Daten!$B$2342=0,"–",INDEX('Stammdaten'!$G$6:$G$105,Daten!$B$2342))
A13: Ergebnis des Halbjahres
B14: Bereich | C14: gewertete Übungen | D14: Prozent | E14: IHK-Note | F14: Hinweis
B15: Praxis | C15: =IF(OR(Daten!$B$2342=0,Daten!$B$2343<1,Daten!$B$2343>8),"",INDEX(Daten!$C$1809:$J$1908,Daten!$B$2342,Daten!$B$2343)) | D15: =IF(OR(Daten!$B$2342=0,Daten!$B$2343<1,Daten!$B$2343>8),"",INDEX(Daten!$C$2019:$J$2118,Daten!$B$2342,Daten!$B$2343)) | E15: =IF(NOT(ISNUMBER(D15)),"",INDEX(Noten,MAX(1,MIN(COUNT(NGrenze),COUNT(NGrenze)+1-COUNTIF(NGrenze,"<="&D15))))&" – "&INDEX(NText,MAX(1,MIN(COUNT(NGrenze),COUNT(NGrenze)+1-COUNTIF(NGrenze,"<="&D15))))) | F15: =IF(C15="","",IF(C15=0,"in diesem Halbjahr nicht bewertet",IF(C15<SchwelleDB,"wenig Datenbasis ("&C15&" Übung"&IF(C15=1,"","en")&")","")))
B16: Theorie | C16: =IF(OR(Daten!$B$2342=0,Daten!$B$2343<1,Daten!$B$2343>8),"",INDEX(Daten!$C$1914:$J$2013,Daten!$B$2342,Daten!$B$2343)) | D16: =IF(OR(Daten!$B$2342=0,Daten!$B$2343<1,Daten!$B$2343>8),"",INDEX(Daten!$C$2124:$J$2223,Daten!$B$2342,Daten!$B$2343)) | E16: =IF(NOT(ISNUMBER(D16)),"",INDEX(Noten,MAX(1,MIN(COUNT(NGrenze),COUNT(NGrenze)+1-COUNTIF(NGrenze,"<="&D16))))&" – "&INDEX(NText,MAX(1,MIN(COUNT(NGrenze),COUNT(NGrenze)+1-COUNTIF(NGrenze,"<="&D16))))) | F16: =IF(C16="","",IF(C16=0,"in diesem Halbjahr nicht bewertet",IF(C16<SchwelleDB,"wenig Datenbasis ("&C16&" Übung"&IF(C16=1,"","en")&")","")))
B17: Gesamt | C17: =IF(OR(Daten!$B$2342=0,Daten!$B$2343<1,Daten!$B$2343>8),"",INDEX(Daten!$C$1704:$J$1803,Daten!$B$2342,Daten!$B$2343)) | D17: =IF(OR(Daten!$B$2342=0,Daten!$B$2343<1,Daten!$B$2343>8),"",INDEX(Daten!$C$2229:$J$2328,Daten!$B$2342,Daten!$B$2343)) | E17: =IF(NOT(ISNUMBER(D17)),"",INDEX(Noten,MAX(1,MIN(COUNT(NGrenze),COUNT(NGrenze)+1-COUNTIF(NGrenze,"<="&D17))))&" – "&INDEX(NText,MAX(1,MIN(COUNT(NGrenze),COUNT(NGrenze)+1-COUNTIF(NGrenze,"<="&D17))))) | F17: =IF(C17="","",IF(C17=0,"in diesem Halbjahr nicht bewertet",IF(C17<SchwelleDB,"wenig Datenbasis ("&C17&" Übung"&IF(C17=1,"","en")&")","")))
A19: Gewertete Übungen in diesem Halbjahr
B20: Übung | D20: Art | E20: Datum | F20: Punkte | G20: Prozent
A21: =IFERROR(SMALL(Daten!$C$2335:$V$2335,1),"") | B21: =IF($A21="","",INDEX(Daten!$C$4:$V$4,$A21)) | D21: =IF($A21="","",INDEX(Daten!$C$6:$V$6,$A21)) | E21: =IF($A21="","",INDEX(Daten!$C$7:$V$7,$A21)) | F21: =IF($A21="","",INDEX(Daten!$C$335:$V$434,Daten!$B$2342,$A21)&" / "&INDEX(Daten!$C$440:$V$539,Daten!$B$2342,$A21)) | G21: =IF($A21="","",INDEX(Daten!$C$20:$V$119,Daten!$B$2342,$A21))
A22: =IFERROR(SMALL(Daten!$C$2335:$V$2335,2),"") | B22: =IF($A22="","",INDEX(Daten!$C$4:$V$4,$A22)) | D22: =IF($A22="","",INDEX(Daten!$C$6:$V$6,$A22)) | E22: =IF($A22="","",INDEX(Daten!$C$7:$V$7,$A22)) | F22: =IF($A22="","",INDEX(Daten!$C$335:$V$434,Daten!$B$2342,$A22)&" / "&INDEX(Daten!$C$440:$V$539,Daten!$B$2342,$A22)) | G22: =IF($A22="","",INDEX(Daten!$C$20:$V$119,Daten!$B$2342,$A22))
A23: =IFERROR(SMALL(Daten!$C$2335:$V$2335,3),"") | B23: =IF($A23="","",INDEX(Daten!$C$4:$V$4,$A23)) | D23: =IF($A23="","",INDEX(Daten!$C$6:$V$6,$A23)) | E23: =IF($A23="","",INDEX(Daten!$C$7:$V$7,$A23)) | F23: =IF($A23="","",INDEX(Daten!$C$335:$V$434,Daten!$B$2342,$A23)&" / "&INDEX(Daten!$C$440:$V$539,Daten!$B$2342,$A23)) | G23: =IF($A23="","",INDEX(Daten!$C$20:$V$119,Daten!$B$2342,$A23))
A24: =IFERROR(SMALL(Daten!$C$2335:$V$2335,4),"") | B24: =IF($A24="","",INDEX(Daten!$C$4:$V$4,$A24)) | D24: =IF($A24="","",INDEX(Daten!$C$6:$V$6,$A24)) | E24: =IF($A24="","",INDEX(Daten!$C$7:$V$7,$A24)) | F24: =IF($A24="","",INDEX(Daten!$C$335:$V$434,Daten!$B$2342,$A24)&" / "&INDEX(Daten!$C$440:$V$539,Daten!$B$2342,$A24)) | G24: =IF($A24="","",INDEX(Daten!$C$20:$V$119,Daten!$B$2342,$A24))
A25: =IFERROR(SMALL(Daten!$C$2335:$V$2335,5),"") | B25: =IF($A25="","",INDEX(Daten!$C$4:$V$4,$A25)) | D25: =IF($A25="","",INDEX(Daten!$C$6:$V$6,$A25)) | E25: =IF($A25="","",INDEX(Daten!$C$7:$V$7,$A25)) | F25: =IF($A25="","",INDEX(Daten!$C$335:$V$434,Daten!$B$2342,$A25)&" / "&INDEX(Daten!$C$440:$V$539,Daten!$B$2342,$A25)) | G25: =IF($A25="","",INDEX(Daten!$C$20:$V$119,Daten!$B$2342,$A25))
A26: =IFERROR(SMALL(Daten!$C$2335:$V$2335,6),"") | B26: =IF($A26="","",INDEX(Daten!$C$4:$V$4,$A26)) | D26: =IF($A26="","",INDEX(Daten!$C$6:$V$6,$A26)) | E26: =IF($A26="","",INDEX(Daten!$C$7:$V$7,$A26)) | F26: =IF($A26="","",INDEX(Daten!$C$335:$V$434,Daten!$B$2342,$A26)&" / "&INDEX(Daten!$C$440:$V$539,Daten!$B$2342,$A26)) | G26: =IF($A26="","",INDEX(Daten!$C$20:$V$119,Daten!$B$2342,$A26))
A27: =IFERROR(SMALL(Daten!$C$2335:$V$2335,7),"") | B27: =IF($A27="","",INDEX(Daten!$C$4:$V$4,$A27)) | D27: =IF($A27="","",INDEX(Daten!$C$6:$V$6,$A27)) | E27: =IF($A27="","",INDEX(Daten!$C$7:$V$7,$A27)) | F27: =IF($A27="","",INDEX(Daten!$C$335:$V$434,Daten!$B$2342,$A27)&" / "&INDEX(Daten!$C$440:$V$539,Daten!$B$2342,$A27)) | G27: =IF($A27="","",INDEX(Daten!$C$20:$V$119,Daten!$B$2342,$A27))
A28: =IFERROR(SMALL(Daten!$C$2335:$V$2335,8),"") | B28: =IF($A28="","",INDEX(Daten!$C$4:$V$4,$A28)) | D28: =IF($A28="","",INDEX(Daten!$C$6:$V$6,$A28)) | E28: =IF($A28="","",INDEX(Daten!$C$7:$V$7,$A28)) | F28: =IF($A28="","",INDEX(Daten!$C$335:$V$434,Daten!$B$2342,$A28)&" / "&INDEX(Daten!$C$440:$V$539,Daten!$B$2342,$A28)) | G28: =IF($A28="","",INDEX(Daten!$C$20:$V$119,Daten!$B$2342,$A28))
A30: Stärken
A36: Entwicklungsziele bis zum nächsten Gespräch
A42: Bestätigung
B44: Datum, Unterschrift Azubi | E44: Datum, Unterschrift Ausbilder/-in
A46: Farblegende | C46: =INDEX(Noten,1)&" – "&INDEX(NText,1) | E46: =INDEX(Noten,2)&" – "&INDEX(NText,2) | G46: =INDEX(Noten,3)&" – "&INDEX(NText,3)
C47: =INDEX(Noten,4)&" – "&INDEX(NText,4) | E47: =INDEX(Noten,5)&" – "&INDEX(NText,5) | G47: =INDEX(Noten,6)&" – "&INDEX(NText,6)
A48: Übungen, bei denen der Azubi nicht bewertet wurde (krank, Urlaub, Berufsschule), sind hier bewusst nicht enthalten – sie zählen weder als 0 Punkte noch im Durchschnitt. Bei einer Wiederholung zählt die im Übungsblatt eingestellte Wertung (Standard: die letzte).

Sheet Halbjahr
A1: Halbjahresauswertung | M1: « Zurück zur Startseite
A2: Stand aller Azubis für ein Halbjahr – Grundlage für die Beurteilungsgespräche
A3: Farben: gelb = hier eintragen · grau-blau = rechnet die Datei selbst · „n.b.“ = nicht bewertet
A4: Halbjahr auswählen | C4: 4 | D4: ="Halbjahr "&$C$4&" = Monat "&($C$4-1)*6+1&" bis "&$C$4*6&" nach dem jeweiligen Ausbildungsstart. Leere Zeilen bedeuten: in diesem Halbjahr wurde noch nichts bewertet."
A6: Nr. | B6: Name | C6: Vorname | D6: Ausbildungsberuf | E6: Jahrgang | F6: LJ | G6: Übungen | H6: Praxis % | I6: Praxis Note | J6: Theorie | K6: Theorie % | L6: Theorie Note | M6: Gesamt % | N6: Gesamt Note | O6: Hinweis
